Workbook
Name inv_3Fios: 'Dados dos Inversores'!$AA$3:$AA$1048518
Name inv_4Fios: 'Dados dos Inversores'!$AB$3:$AB$1048518
Name inv_Altura: 'Dados dos Inversores'!$E$2:$E$1048518
Name inv_Comprimento: 'Dados dos Inversores'!$C$3:$C$1048518
Name inv_CorrCAMax: 'Dados dos Inversores'!$AE$3:$AE$1048518
Name inv_CorrCurtoMPPT: 'Dados dos Inversores'!$X$3:$X$1048518
Name inv_CorrMaxMPPT: 'Dados dos Inversores'!$Y$3:$Y$1048518
Name inv_Dados: 'Dados dos Inversores'!$A$3:$AG$1048518
Name inv_Display: 'Dados dos Inversores'!$J$3:$J$1048518
Name inv_Fabricante: 'Dados dos Inversores'!$B$3:$B$1048518
Name inv_Largura: 'Dados dos Inversores'!$D$3:$D$1048518
Name inv_Led: 'Dados dos Inversores'!$K$3:$K$1048518
Name inv_mod: Inicio!$H$2
Name inv_Modelo: 'Dados dos Inversores'!$A$3:$A$1048518
Name inv_MonoBi: 'Dados dos Inversores'!$Z$3:$Z$1048518
Name inv_Peso: 'Dados dos Inversores'!$F$2:$F$1048518
Name inv_PotMax: 'Dados dos Inversores'!$N$3:$N$1048518
Name inv_potnom: Inicio!$H$3
Name inv_potnom50: Inicio!$H$4
Name inv_PotNominal: 'Dados dos Inversores'!$M$3:$M$1048518
Name inv_QuantMPPT: 'Dados dos Inversores'!$O$3:$O$1048518
Name inv_QuantStrMPPT: 'Dados dos Inversores'!$Q$3:$Q$1048518
Name inv_RS485: 'Dados dos Inversores'!$I$3:$I$1048518
Name inv_TenFLMaxMPPT: 'Dados dos Inversores'!$U$3:$U$1048518
Name inv_TenFLMinMPPT: 'Dados dos Inversores'!$V$3:$V$1048518
Name inv_TenNomCAMax: 'Dados dos Inversores'!$AC$3:$AC$1048518
Name inv_TenNomCAMin: 'Dados dos Inversores'!$AD$3:$AD$1048518
Name inv_TenNomMPPT: 'Dados dos Inversores'!$W$3:$W$1048518
Name inv_TenOpMaxMPPT: 'Dados dos Inversores'!$T$3:$T$1048518
Name inv_TenOpMinMPPT: 'Dados dos Inversores'!$T$3:$T$1048518
Name inv_TenPartMaxMPPT: 'Dados dos Inversores'!$R$3:$R$1048518
Name inv_TenPartMinMPPT: 'Dados dos Inversores'!$S$3:$S$1048518
Name inv_USB: 'Dados dos Inversores'!$L$3:$L$1048518
Name inv_Ventilacao: 'Dados dos Inversores'!$G$3:$G$1048518
Name inv_Wifi: 'Dados dos Inversores'!$H$3:$H$1048518
Name Ipmax_max: Inicio!$E$9
Name Ipmax_STC: Inicio!$E$14
Name Isc_coef: Inicio!$E$16
Name Isc_max: Inicio!$E$8
Name Isc_STC: Inicio!$E$13
Name mod_Altura: 'Dados dos Modulos'!$G$2:$G$1048576
Name mod_CoefCor: 'Dados dos Modulos'!$P$2:$P$1048576
Name mod_CoefPot: 'Dados dos Modulos'!$N$2:$N$1048576
Name mod_CofTen: 'Dados dos Modulos'!$O$2:$O$1048576
Name mod_Comprimento: 'Dados dos Modulos'!$E$2:$E$1048576
Name mod_Dados: 'Dados dos Modulos'!$A$2:$P$1048576
Name mod_EstruturaCristalina: 'Dados dos Modulos'!$D$2:$D$1048576
Name mod_Fabricante: 'Dados dos Modulos'!$B$2:$B$1048576
Name mod_Face: 'Dados dos Modulos'!$C$2:$C$1048576
Name mod_Ipmax: 'Dados dos Modulos'!$M$2:$M$1048576
Name mod_Isc: 'Dados dos Modulos'!$L$2:$L$1048576
Name mod_Largura: 'Dados dos Modulos'!$F$2:$F$1048576
Name mod_mod: Inicio!$E$2
Name mod_Modelo: 'Dados dos Modulos'!$A$2:$A$1048576
Name mod_Peso: 'Dados dos Modulos'!$H$2:$H$1048576
Name mod_PotenciaNominal: 'Dados dos Modulos'!$I$2:$I$1048576
Name mod_Voc: 'Dados dos Modulos'!$J$2:$J$1048576
Name mod_Vpmax: 'Dados dos Modulos'!$K$2:$K$1048576
Name PN_coef: Inicio!$E$17
Name pot_Modulo: Inicio!$E$3

Sheet Compare Inversores
C1: WPV 550 HMM3 | E1: BYD550MLK-36 | G1: JKM555M-72HL4 | I1: JAM66D42-570/MB | K1: CHSM72N(DG)/F-BH-570 | M1: JKM585N 72HL4-V | O1: CHSM78N(DG)/F-BH-635 | Q1: HS-210-B132 DS700 | S1: TSM-710NEG21C.20 | U1: LR5-72HTH-575M
B2: Sobrecarga | C2: Quantidade Máxima | D2: Potência (kWp) | E2: Quantidade Máxima | F2: Potência (kWp) | G2: Quantidade Máxima | H2: Potência (kWp) | I2: Quantidade Máxima | J2: Potência (kWp) | K2: Quantidade Máxima | L2: Potência (kWp) | M2: Quantidade Máxima | N2: Potência (kWp) | O2: Quantidade Máxima | P2: Potência (kWp) | Q2: Quantidade Máxima | R2: Potência (kWp) | S2: Quantidade Máxima | T2: Potência (kWp) | U2: Quantidade Máxima | V2: Potência (kWp)
A3: SIW500G T075 W0 | B3: =VLOOKUP($A3,inv_Dados,13,0)*(1+VLOOKUP($A3,inv_Dados,32,0)/100) -> 160200 | C3: =IF(Formulas!$F27=0,"Não suporta",Formulas!$F27) -> 205 | D3: =Formulas!$F28 -> 112750 | E3: =IF(Formulas!$I27=0,"Não suporta",Formulas!$I27) -> 205 | F3: =Formulas!$I28 -> 112750 | G3: =IF(Formulas!$L27=0,"Não suporta",Formulas!$L27) -> 203 | H3: =Formulas!$L28 -> 112665 | I3: =IF(Formulas!$O27=0,"Não suporta",Formulas!$O27) -> 198 | J3: =Formulas!$O28 -> 112860 | K3: =IF(Formulas!$R27=0,"Não suporta",Formulas!$R27) -> 198 | L3: =Formulas!$R28 -> 112860 | M3: =IF(Formulas!$U27=0,"Não suporta",Formulas!$U27) -> 193 | N3: =Formulas!$U28 -> 112905 | O3: =IF(Formulas!$X27=0,"Não suporta",Formulas!$X27) -> 178 | P3: =Formulas!$X28 -> 113030 | Q3: =IF(Formulas!$AA27=0,"Não suporta",Formulas!$AA27) -> 161 | R3: =Formulas!$AA28 -> 112700 | S3: =IF(Formulas!$AD27=0,"Não suporta",Formulas!$AD27) -> 159 | T3: =Formulas!$AD28 -> 112890 | U3: =IF(Formulas!$AG27=0,"Não suporta",Formulas!$AG27) -> 196 | V3: =Formulas!$AG28 -> 112700
A4: SIW300H M030 W00 | B4: =VLOOKUP($A4,inv_Dados,13,0)*(1+VLOOKUP($A4,inv_Dados,32,0)/100) -> 3450 | C4: =IF(Formulas!$F41=0,"Não suporta",Formulas!$F41) -> 10 | D4: =Formulas!$F42 -> 5500 | E4: =IF(Formulas!$I41=0,"Não suporta",Formulas!$I41) -> 10 | F4: =Formulas!$I42 -> 5500 | G4: =IF(Formulas!$L41=0,"Não suporta",Formulas!$L41) -> 10 | H4: =Formulas!$L42 -> 5550 | I4: =IF(Formulas!$O41=0,"Não suporta",Formulas!$O41) -> 10 | J4: =Formulas!$O42 -> 5700 | K4: =IF(Formulas!$R41=0,"Não suporta",Formulas!$R41) -> 10 | L4: =Formulas!$R42 -> 5700 | M4: =IF(Formulas!$U41=0,"Não suporta",Formulas!$U41) -> 10 | N4: =Formulas!$U42 -> 5850 | O4: =IF(Formulas!$X41=0,"Não suporta",Formulas!$X41) -> 9 | P4: =Formulas!$X42 -> 5715 | Q4: =IF(Formulas!$AA41=0,"Não suporta",Formulas!$AA41) -> Não suporta | R4: =Formulas!$AA42 -> 0 | S4: =IF(Formulas!$AD41=0,"Não suporta",Formulas!$AD41) -> Não suporta | T4: =Formulas!$AD42 -> 0 | U4: =IF(Formulas!$AG41=0,"Não suporta",Formulas!$AG41) -> 10 | V4: =Formulas!$AG42 -> 5750
A5: SIW610 T018 W0 | B5: =VLOOKUP($A5,inv_Dados,13,0)*(1+VLOOKUP($A5,inv_Dados,32,0)/100) -> 23040 | C5: =IF(Formulas!$F55=0,"Não suporta",Formulas!$F55) -> 32 | D5: =Formulas!$F56 -> 17600 | E5: =IF(Formulas!$I55=0,"Não suporta",Formulas!$I55) -> 32 | F5: =Formulas!$I56 -> 17600 | G5: =IF(Formulas!$L55=0,"Não suporta",Formulas!$L55) -> 32 | H5: =Formulas!$L56 -> 17760 | I5: =IF(Formulas!$O55=0,"Não suporta",Formulas!$O55) -> 31 | J5: =Formulas!$O56 -> 17670 | K5: =IF(Formulas!$R55=0,"Não suporta",Formulas!$R55) -> 31 | L5: =Formulas!$R56 -> 17670 | M5: =IF(Formulas!$U55=0,"Não suporta",Formulas!$U55) -> 30 | N5: =Formulas!$U56 -> 17550 | O5: =IF(Formulas!$X55=0,"Não suporta",Formulas!$X55) -> 28 | P5: =Formulas!$X56 -> 17780 | Q5: =IF(Formulas!$AA55=0,"Não suporta",Formulas!$AA55) -> 25 | R5: =Formulas!$AA56 -> 17500 | S5: =IF(Formulas!$AD55=0,"Não suporta",Formulas!$AD55) -> 25 | T5: =Formulas!$AD56 -> 17750 | U5: =IF(Formulas!$AG55=0,"Não suporta",Formulas!$AG55) -> 31 | V5: =Formulas!$AG56 -> 17825
A6: SIW610 T075 W0 | B6: =VLOOKUP($A6,inv_Dados,13,0)*(1+VLOOKUP($A6,inv_Dados,32,0)/100) -> 160500 | C6: =IF(Formulas!$F69=0,"Não suporta",Formulas!$F69) -> 137 | D6: =Formulas!$F70 -> 75350 | E6: =IF(Formulas!$I69=0,"Não suporta",Formulas!$I69) -> 137 | F6: =Formulas!$I70 -> 75350 | G6: =IF(Formulas!$L69=0,"Não suporta",Formulas!$L69) -> 135 | H6: =Formulas!$L70 -> 74925 | I6: =IF(Formulas!$O69=0,"Não suporta",Formulas!$O69) -> 132 | J6: =Formulas!$O70 -> 75240 | K6: =IF(Formulas!$R69=0,"Não suporta",Formulas!$R69) -> 132 | L6: =Formulas!$R70 -> 75240 | M6: =IF(Formulas!$U69=0,"Não suporta",Formulas!$U69) -> 128 | N6: =Formulas!$U70 -> 74880 | O6: =IF(Formulas!$X56=0,"Não suporta",Formulas!$X69) -> 118 | P6: =Formulas!$X70 -> 74930 | Q6: =IF(Formulas!$AA69=0,"Não suporta",Formulas!$AA69) -> 107 | R6: =Formulas!$AA70 -> 74900 | S6: =IF(Formulas!$AD69=0,"Não suporta",Formulas!$AD69) -> 106 | T6: =Formulas!$AD70 -> 75260 | U6: =IF(Formulas!$AG69=0,"Não suporta",Formulas!$AG69) -> 131 | V6: =Formulas!$AG70 -> 75325
A7: T12 | B7: =VLOOKUP($A7,inv_Dados,13,0)*(1+VLOOKUP($A7,inv_Dados,32,0)/100) -> 14088 | C7: =IF(Formulas!$F83=0,"Não suporta",Formulas!$F83) -> 32 | D7: =Formulas!$F84 -> 17600 | E7: =IF(Formulas!$I83=0,"Não suporta",Formulas!$I83) -> 32 | F7: =Formulas!$I84 -> 17600 | G7: =IF(Formulas!$L83=0,"Não suporta",Formulas!$L83) -> 32 | H7: =Formulas!$L84 -> 17760 | I7: =IF(Formulas!$O83=0,"Não suporta",Formulas!$O83) -> Não suporta | J7: =Formulas!$O84 -> 0 | K7: =IF(Formulas!$R83=0,"Não suporta",Formulas!$R83) -> 31 | L7: =Formulas!$R84 -> 17670 | M7: =IF(Formulas!$U83=0,"Não suporta",Formulas!$U83) -> 30 | N7: =Formulas!$U84 -> 17550 | O7: =IF(Formulas!$X83=0,"Não suporta",Formulas!$X83) -> Não suporta | P7: =Formulas!$X84 -> 0 | Q7: =IF(Formulas!$AA83=0,"Não suporta",Formulas!$AA83) -> Não suporta | R7: =Formulas!$AA84 -> 0 | S7: =IF(Formulas!$AD83=0,"Não suporta",Formulas!$AD83) -> Não suporta | T7: =Formulas!$AD84 -> 0 | U7: =IF(Formulas!$AG83=0,"Não suporta",Formulas!$AG83) -> 31 | V7: =Formulas!$AG84 -> 17825
A8: SIW300H M030 L1 | B8: =VLOOKUP($A8,inv_Dados,13,0)*(1+VLOOKUP($A8,inv_Dados,32,0)/100) -> 3450 | C8: =IF(Formulas!$F97=0,"Não suporta",Formulas!$F97) -> 8 | D8: =Formulas!$F98 -> 4400 | E8: =IF(Formulas!$I97=0,"Não suporta",Formulas!$I97) -> 8 | F8: =Formulas!$I98 -> 4400 | G8: =IF(Formulas!$L97=0,"Não suporta",Formulas!$L97) -> 8 | H8: =Formulas!$L98 -> 4440 | I8: =IF(Formulas!$O97=0,"Não suporta",Formulas!$O97) -> Não suporta | J8: =Formulas!$O98 -> 0 | K8: =IF(Formulas!$R97=0,"Não suporta",Formulas!$R97) -> 7 | L8: =Formulas!$R98 -> 3990 | M8: =IF(Formulas!$U97=0,"Não suporta",Formulas!$U97) -> 7 | N8: =Formulas!$U98 -> 4095 | O8: =IF(Formulas!$X97=0,"Não suporta",Formulas!$X97) -> Não suporta | P8: =Formulas!$X98 -> 0 | Q8: =IF(Formulas!$AA97=0,"Não suporta",Formulas!$AA97) -> Não suporta | R8: =Formulas!$AA98 -> 0 | S8: =IF(Formulas!$AD97=0,"Não suporta",Formulas!$AD97) -> Não suporta | T8: =Formulas!$AD98 -> 0 | U8: =IF(Formulas!$AG97=0,"Não suporta",Formulas!$AG97) -> 7 | V8: =Formulas!$AG98 -> 4025
A9: SIW300H M060 L1 | B9: =VLOOKUP($A9,inv_Dados,13,0)*(1+VLOOKUP($A9,inv_Dados,32,0)/100) -> 7620 | C9: =IF(Formulas!$F111=0,"Não suporta",Formulas!$F111) -> 16 | D9: =Formulas!$F112 -> 8800 | E9: =IF(Formulas!$I111=0,"Não suporta",Formulas!$I111) -> 16 | F9: =Formulas!$I112 -> 8800 | G9: =IF(Formulas!$L111=0,"Não suporta",Formulas!$L111) -> 16 | H9: =Formulas!$L112 -> 8880 | I9: =IF(Formulas!$O111=0,"Não suporta",Formulas!$O111) -> Não suporta | J9: =Formulas!$O112 -> 0 | K9: =IF(Formulas!$R111=0,"Não suporta",Formulas!$R111) -> 15 | L9: =Formulas!$R112 -> 8550 | M9: =IF(Formulas!$U111=0,"Não suporta",Formulas!$U111) -> 15 | N9: =Formulas!$U112 -> 8775 | O9: =IF(Formulas!$X111=0,"Não suporta",Formulas!$X111) -> Não suporta | P9: =Formulas!$X112 -> 0 | Q9: =IF(Formulas!$AA111=0,"Não suporta",Formulas!$AA111) -> Não suporta | R9: =Formulas!$AA112 -> 0 | S9: =IF(Formulas!$AD111=0,"Não suporta",Formulas!$AD111) -> Não suporta | T9: =Formulas!$AD112 -> 0 | U9: =IF(Formulas!$AG111=0,"Não suporta",Formulas!$AG111) -> 15 | V9: =Formulas!$AG112 -> 8625
A10: SIW300H M075 W00 | B10: =VLOOKUP($A10,inv_Dados,13,0)*(1+VLOOKUP($A10,inv_Dados,32,0)/100) -> 10056.75 | C10: =IF(Formulas!$F125=0,"Não suporta",Formulas!$F125) -> 20 | D10: =Formulas!$F126 -> 11000 | E10: =IF(Formulas!$I125=0,"Não suporta",Formulas!$I125) -> 20 | F10: =Formulas!$I126 -> 11000 | G10: =IF(Formulas!$L125=0,"Não suporta",Formulas!$L125) -> 20 | H10: =Formulas!$L126 -> 11100 | I10: =IF(Formulas!$O125=0,"Não suporta",Formulas!$O125) -> 19 | J10: =Formulas!$O126 -> 10830 | K10: =IF(Formulas!$R125=0,"Não suporta",Formulas!$R125) -> 19 | L10: =Formulas!$R126 -> 10830 | M10: =IF(Formulas!$U125=0,"Não suporta",Formulas!$U125) -> 19 | N10: =Formulas!$U126 -> 11115 | O10: =IF(Formulas!$X125=0,"Não suporta",Formulas!$X125) -> 17 | P10: =Formulas!$X126 -> 10795 | Q10: =IF(Formulas!$AA125=0,"Não suporta",Formulas!$AA125) -> 16 | R10: =Formulas!$AA126 -> 11200 | S10: =IF(Formulas!$AD125=0,"Não suporta",Formulas!$AD125) -> 15 | T10: =Formulas!$AD126 -> 10650 | U10: =IF(Formulas!$AG125=0,"Não suporta",Formulas!$AG125) -> 19 | V10: =Formulas!$AG126 -> 10925
A11: SIW400G T050 W00 | B11: =VLOOKUP($A11,inv_Dados,13,0)*(1+VLOOKUP($A11,inv_Dados,32,0)/100) -> 91800 | C11: =IF(Formulas!$F139=0,"Não suporta",Formulas!$F139) -> 137 | D11: =Formulas!$F140 -> 75350 | E11: =IF(Formulas!$I139=0,"Não suporta",Formulas!$I139) -> 137 | F11: =Formulas!$I140 -> 75350 | G11: =IF(Formulas!$L139=0,"Não suporta",Formulas!$L139) -> 135 | H11: =Formulas!$L140 -> 74925 | I11: =IF(Formulas!$O139=0,"Não suporta",Formulas!$O139) -> 132 | J11: =Formulas!$O140 -> 75240 | K11: =IF(Formulas!$R139=0,"Não suporta",Formulas!$R139) -> 132 | L11: =Formulas!$R140 -> 75240 | M11: =IF(Formulas!$U139=0,"Não suporta",Formulas!$U139) -> 128 | N11: =Formulas!$U140 -> 74880 | O11: =IF(Formulas!$X139=0,"Não suporta",Formulas!$X139) -> 118 | P11: =Formulas!$X140 -> 74930 | Q11: =IF(Formulas!$AA139=0,"Não suporta",Formulas!$AA139) -> 107 | R11: =Formulas!$AA140 -> 74900 | S11: =IF(Formulas!$AD139=0,"Não suporta",Formulas!$AD139) -> 106 | T11: =Formulas!$AD140 -> 75260 | U11: =IF(Formulas!$AG139=0,"Não suporta",Formulas!$AG139) -> 131 | V11: =Formulas!$AG140 -> 75325
A12: SIW400G T060 W00 | B12: =VLOOKUP($A12,inv_Dados,13,0)*(1+VLOOKUP($A12,inv_Dados,32,0)/100) -> 120180 | C12: =IF(Formulas!$F153=0,"Não suporta",Formulas!$F153) -> 164 | D12: =Formulas!$F154 -> 90200 | E12: =IF(Formulas!$I153=0,"Não suporta",Formulas!$I153) -> 164 | F12: =Formulas!$I154 -> 90200 | G12: =IF(Formulas!$L153=0,"Não suporta",Formulas!$L153) -> 162 | H12: =Formulas!$L154 -> 89910 | I12: =IF(Formulas!$O153=0,"Não suporta",Formulas!$O153) -> 158 | J12: =Formulas!$O154 -> 90060 | K12: =IF(Formulas!$R153=0,"Não suporta",Formulas!$R153) -> 158 | L12: =Formulas!$R154 -> 90060 | M12: =IF(Formulas!$U153=0,"Não suporta",Formulas!$U153) -> 154 | N12: =Formulas!$U154 -> 90090 | O12: =IF(Formulas!$X153=0,"Não suporta",Formulas!$X153) -> 142 | P12: =Formulas!$X154 -> 90170 | Q12: =IF(Formulas!$AA153=0,"Não suporta",Formulas!$AA153) -> 129 | R12: =Formulas!$AA154 -> 90300 | S12: =IF(Formulas!$AD153=0,"Não suporta",Formulas!$AD153) -> 127 | T12: =Formulas!$AD154 -> 90170 | U12: =IF(Formulas!$AG153=0,"Não suporta",Formulas!$AG153) -> 157 | V12: =Formulas!$AG154 -> 90275
B13: =VLOOKUP($A13,inv_Dados,13,0)*(1+VLOOKUP($A13,inv_Dados,32,0)/100) -> #N/A
B14: =VLOOKUP($A14,inv_Dados,13,0)*(1+VLOOKUP($A14,inv_Dados,32,0)/100) -> #N/A
B15: =VLOOKUP($A15,inv_Dados,13,0)*(1+VLOOKUP($A15,inv_Dados,32,0)/100) -> #N/A
B16: =VLOOKUP($A16,inv_Dados,13,0)*(1+VLOOKUP($A16,inv_Dados,32,0)/100) -> #N/A
B17: =VLOOKUP($A17,inv_Dados,13,0)*(1+VLOOKUP($A17,inv_Dados,32,0)/100) -> #N/A
B18: =VLOOKUP($A18,inv_Dados,13,0)*(1+VLOOKUP($A18,inv_Dados,32,0)/100) -> #N/A
B19: =VLOOKUP($A19,inv_Dados,13,0)*(1+VLOOKUP($A19,inv_Dados,32,0)/100) -> #N/A
B20: =VLOOKUP($A20,inv_Dados,13,0)*(1+VLOOKUP($A20,inv_Dados,32,0)/100) -> #N/A
B21: =VLOOKUP($A21,inv_Dados,13,0)*(1+VLOOKUP($A21,inv_Dados,32,0)/100) -> #N/A
B22: =VLOOKUP($A22,inv_Dados,13,0)*(1+VLOOKUP($A22,inv_Dados,32,0)/100) -> #N/A
B23: =VLOOKUP($A23,inv_Dados,13,0)*(1+VLOOKUP($A23,inv_Dados,32,0)/100) -> #N/A
B24: =VLOOKUP($A24,inv_Dados,13,0)*(1+VLOOKUP($A24,inv_Dados,32,0)/100) -> #N/A
... B291: =VLOOKUP($A291,inv_Dados,13,0)*(1+VLOOKUP($A291,inv_Dados,32,0)/100) -> #N/A

Sheet Formulas
E1: Módulos
B2: Ambiente | E2: ='Compare Inversores'!C1 -> WPV 550 HMM3 | H2: ='Compare Inversores'!E1 -> BYD550MLK-36 | K2: ='Compare Inversores'!G1 -> JKM555M-72HL4 | N2: ='Compare Inversores'!I1 -> JAM66D42-570/MB | Q2: ='Compare Inversores'!K1 -> CHSM72N(DG)/F-BH-570 | T2: ='Compare Inversores'!M1 -> JKM585N 72HL4-V | W2: ='Compare Inversores'!O1 -> CHSM78N(DG)/F-BH-635 | Z2: ='Compare Inversores'!Q1 -> HS-210-B132 DS700 | AC2: ='Compare Inversores'!S1 -> TSM-710NEG21C.20 | AF2: ='Compare Inversores'!U1 -> LR5-72HTH-575M
E3: Pôtencia | F3: =VLOOKUP(E$2,mod_Dados,9,0) -> 550 | H3: Pôtencia | I3: =VLOOKUP(H$2,mod_Dados,9,0) -> 550 | K3: Pôtencia | L3: =VLOOKUP(K$2,mod_Dados,9,0) -> 555 | N3: Pôtencia | O3: =VLOOKUP(N$2,mod_Dados,9,0) -> 570 | Q3: Pôtencia | R3: =VLOOKUP(Q$2,mod_Dados,9,0) -> 570 | T3: Pôtencia | U3: =VLOOKUP(T$2,mod_Dados,9,0) -> 585 | W3: Pôtencia | X3: =VLOOKUP(W$2,mod_Dados,9,0) -> 635 | Z3: Pôtencia | AA3: =VLOOKUP(Z$2,mod_Dados,9,0) -> 700 | AC3: Pôtencia | AD3: =VLOOKUP(AC$2,mod_Dados,9,0) -> 710 | AF3: Pôtencia | AG3: =VLOOKUP(AF$2,mod_Dados,9,0) -> 575
B4: Temperatura mínima da célula (°C) | E4: Voc (STC) | F4: =VLOOKUP(E$2,mod_Dados,10,0) -> 49.9 | H4: Voc (STC) | I4: =VLOOKUP(H$2,mod_Dados,10,0) -> 50.32 | K4: Voc (STC) | L4: =VLOOKUP(K$2,mod_Dados,10,0) -> 49.72 | N4: Voc (STC) | O4: =VLOOKUP(N$2,mod_Dados,10,0) -> 47.78 | Q4: Voc (STC) | R4: =VLOOKUP(Q$2,mod_Dados,10,0) -> 50.9 | T4: Voc (STC) | U4: =VLOOKUP(T$2,mod_Dados,10,0) -> 52.47 | W4: Voc (STC) | X4: =VLOOKUP(W$2,mod_Dados,10,0) -> 56.41 | Z4: Voc (STC) | AA4: =VLOOKUP(Z$2,mod_Dados,10,0) -> 49.77 | AC4: Voc (STC) | AD4: =VLOOKUP(AC$2,mod_Dados,10,0) -> 49 | AF4: Voc (STC) | AG4: =VLOOKUP(AF$2,mod_Dados,10,0) -> 52.06
B5: 10 | E5: Vpmax (STC) | F5: =VLOOKUP(E$2,mod_Dados,11,0) -> 41.96 | H5: Vpmax (STC) | I5: =VLOOKUP(H$2,mod_Dados,11,0) -> 42.49 | K5: Vpmax (STC) | L5: =VLOOKUP(K$2,mod_Dados,11,0) -> 40.99 | N5: Vpmax (STC) | O5: =VLOOKUP(N$2,mod_Dados,11,0) -> 40 | Q5: Vpmax (STC) | R5: =VLOOKUP(Q$2,mod_Dados,11,0) -> 42.77 | T5: Vpmax (STC) | U5: =VLOOKUP(T$2,mod_Dados,11,0) -> 43.53 | W5: Vpmax (STC) | X5: =VLOOKUP(W$2,mod_Dados,11,0) -> 46.62 | Z5: Vpmax (STC) | AA5: =VLOOKUP(Z$2,mod_Dados,11,0) -> 41.78 | AC5: Vpmax (STC) | AD5: =VLOOKUP(AC$2,mod_Dados,11,0) -> 40.9 | AF5: Vpmax (STC) | AG5: =VLOOKUP(AF$2,mod_Dados,11,0) -> 43.91
B6: Temperatura máxima da célula (°C) | E6: Isc (STC) | F6: =VLOOKUP(E$2,mod_Dados,12,0) -> 14 | H6: Isc (STC) | I6: =VLOOKUP(H$2,mod_Dados,12,0) -> 13.61 | K6: Isc (STC) | L6: =VLOOKUP(K$2,mod_Dados,12,0) -> 14.12 | N6: Isc (STC) | O6: =VLOOKUP(N$2,mod_Dados,12,0) -> 15.11 | Q6: Isc (STC) | R6: =VLOOKUP(Q$2,mod_Dados,12,0) -> 14.1 | T6: Isc (STC) | U6: =VLOOKUP(T$2,mod_Dados,12,0) -> 14.07 | W6: Isc (STC) | X6: =VLOOKUP(W$2,mod_Dados,12,0) -> 14.27 | Z6: Isc (STC) | AA6: =VLOOKUP(Z$2,mod_Dados,12,0) -> 17.81 | AC6: Isc (STC) | AD6: =VLOOKUP(AC$2,mod_Dados,12,0) -> 18.4 | AF6: Isc (STC) | AG6: =VLOOKUP(AF$2,mod_Dados,12,0) -> 14.14
B7: 50 | E7: Ipmax (STC) | F7: =VLOOKUP(E$2,mod_Dados,13,0) -> 13.11 | H7: Ipmax (STC) | I7: =VLOOKUP(H$2,mod_Dados,13,0) -> 12.94 | K7: Ipmax (STC) | L7: =VLOOKUP(K$2,mod_Dados,13,0) -> 13.54 | N7: Ipmax (STC) | O7: =VLOOKUP(N$2,mod_Dados,13,0) -> 14.25 | Q7: Ipmax (STC) | R7: =VLOOKUP(Q$2,mod_Dados,13,0) -> 13.33 | T7: Ipmax (STC) | U7: =VLOOKUP(T$2,mod_Dados,13,0) -> 13.44 | W7: Ipmax (STC) | X7: =VLOOKUP(W$2,mod_Dados,13,0) -> 13.62 | Z7: Ipmax (STC) | AA7: =VLOOKUP(Z$2,mod_Dados,13,0) -> 16.76 | AC7: Ipmax (STC) | AD7: =VLOOKUP(AC$2,mod_Dados,13,0) -> 17.36 | AF7: Ipmax (STC) | AG7: =VLOOKUP(AF$2,mod_Dados,13,0) -> 13.1
E8: Coef. Temp Voc | F8: =VLOOKUP(E$2,mod_Dados,15,0) -> -0.27 | H8: Coef. Temp Voc | I8: =VLOOKUP(H$2,mod_Dados,15,0) -> -0.3 | K8: Coef. Temp Voc | L8: =VLOOKUP(K$2,mod_Dados,15,0) -> -0.28 | N8: Coef. Temp Voc | O8: =VLOOKUP(N$2,mod_Dados,15,0) -> -0.3 | Q8: Coef. Temp Voc | R8: =VLOOKUP(Q$2,mod_Dados,15,0) -> -0.25 | T8: Coef. Temp Voc | U8: =VLOOKUP(T$2,mod_Dados,15,0) -> -0.29 | W8: Coef. Temp Voc | X8: =VLOOKUP(W$2,mod_Dados,15,0) -> -0.25 | Z8: Coef. Temp Voc | AA8: =VLOOKUP(Z$2,mod_Dados,15,0) -> -0.22 | AC8: Coef. Temp Voc | AD8: =VLOOKUP(AC$2,mod_Dados,15,0) -> -0.29 | AF8: Coef. Temp Voc | AG8: =VLOOKUP(AF$2,mod_Dados,15,0) -> -0.23
B9: Tolerância de potência (%) | E9: Coef. Temp Isc | F9: =VLOOKUP(E$2,mod_Dados,16,0) -> 0.045 | H9: Coef. Temp Isc | I9: =VLOOKUP(H$2,mod_Dados,16,0) -> 0.06 | K9: Coef. Temp Isc | L9: =VLOOKUP(K$2,mod_Dados,16,0) -> 0.048 | N9: Coef. Temp Isc | O9: =VLOOKUP(N$2,mod_Dados,16,0) -> 0.046 | Q9: Coef. Temp Isc | R9: =VLOOKUP(Q$2,mod_Dados,16,0) -> 0.043 | T9: Coef. Temp Isc | U9: =VLOOKUP(T$2,mod_Dados,16,0) -> 0.045 | W9: Coef. Temp Isc | X9: =VLOOKUP(W$2,mod_Dados,16,0) -> 0.043 | Z9: Coef. Temp Isc | AA9: =VLOOKUP(Z$2,mod_Dados,16,0) -> 0.04 | AC9: Coef. Temp Isc | AD9: =VLOOKUP(AC$2,mod_Dados,16,0) -> 0.04 | AF9: Coef. Temp Isc | AG9: =VLOOKUP(AF$2,mod_Dados,16,0) -> 0.05
B10: 0.5
B11: Tolerância de corrente de operação (%) | E11: Tensão mínima de circuito aberto | F11: =F$4*(1+(($B$7-25)*F$8/100)) -> 46.53175 | H11: Tensão mínima de circuito aberto | I11: =I$4*(1+(($B$7-25)*I$8/100)) -> 46.546 | K11: Tensão mínima de circuito aberto | L11: =L$4*(1+(($B$7-25)*L$8/100)) -> 46.2396 | N11: Tensão mínima de circuito aberto | O11: =O$4*(1+(($B$7-25)*O$8/100)) -> 44.1965 | Q11: Tensão mínima de circuito aberto | R11: =R$4*(1+(($B$7-25)*R$8/100)) -> 47.71875 | T11: Tensão mínima de circuito aberto | U11: =U$4*(1+(($B$7-25)*U$8/100)) -> 48.665925 | W11: Tensão mínima de circuito aberto | X11: =X$4*(1+(($B$7-25)*X$8/100)) -> 52.884375 | Z11: Tensão mínima de circuito aberto | AA11: =AA$4*(1+(($B$7-25)*AA$8/100)) -> 47.03265 | AC11: Tensão mínima de circuito aberto | AD11: =AD$4*(1+(($B$7-25)*AD$8/100)) -> 45.4475 | AF11: Tensão mínima de circuito aberto | AG11: =AG$4*(1+(($B$7-25)*AG$8/100)) -> 49.06655
B12: 10 | E12: Tensão máxima de circuito aberto | F12: =F$4*(1+(($B$5-25)*F$8/100)) -> 51.92095 | H12: Tensão máxima de circuito aberto | I12: =I$4*(1+(($B$5-25)*I$8/100)) -> 52.5844 | K12: Tensão máxima de circuito aberto | L12: =L$4*(1+(($B$5-25)*L$8/100)) -> 51.80824 | N12: Tensão máxima de circuito aberto | O12: =O$4*(1+(($B$5-25)*O$8/100)) -> 49.9301 | Q12: Tensão máxima de circuito aberto | R12: =R$4*(1+(($B$5-25)*R$8/100)) -> 52.80875 | T12: Tensão máxima de circuito aberto | U12: =U$4*(1+(($B$5-25)*U$8/100)) -> 54.752445 | W12: Tensão máxima de circuito aberto | X12: =X$4*(1+(($B$5-25)*X$8/100)) -> 58.525375 | Z12: Tensão máxima de circuito aberto | AA12: =AA$4*(1+(($B$5-25)*AA$8/100)) -> 51.41241 | AC12: Tensão máxima de circuito aberto | AD12: =AD$4*(1+(($B$5-25)*AD$8/100)) -> 51.1315 | AF12: Tensão máxima de circuito aberto | AG12: =AG$4*(1+(($B$5-25)*AG$8/100)) -> 53.85607
E13: Tensão mínima em máxima potência | F13: =F$5*(1+(($B$7-25)*F$8/100)) -> 39.1277 | H13: Tensão mínima em máxima potência | I13: =I$5*(1+(($B$7-25)*I$8/100)) -> 39.30325 | K13: Tensão mínima em máxima potência | L13: =L$5*(1+(($B$7-25)*L$8/100)) -> 38.1207 | N13: Tensão mínima em máxima potência | O13: =O$5*(1+(($B$7-25)*O$8/100)) -> 37 | Q13: Tensão mínima em máxima potência | R13: =R$5*(1+(($B$7-25)*R$8/100)) -> 40.096875 | T13: Tensão mínima em máxima potência | U13: =U$5*(1+(($B$7-25)*U$8/100)) -> 40.374075 | W13: Tensão mínima em máxima potência | X13: =X$5*(1+(($B$7-25)*X$8/100)) -> 43.70625 | Z13: Tensão mínima em máxima potência | AA13: =AA$5*(1+(($B$7-25)*AA$8/100)) -> 39.4821 | AC13: Tensão mínima em máxima potência | AD13: =AD$5*(1+(($B$7-25)*AD$8/100)) -> 37.93475 | AF13: Tensão mínima em máxima potência | AG13: =AG$5*(1+(($B$7-25)*AG$8/100)) -> 41.385175
E14: Tensão máxima em máxima potência | F14: =F$5*(1+(($B$5-25)*F$8/100)) -> 43.65938 | H14: Tensão máxima em máxima potência | I14: =I$5*(1+(($B$5-25)*I$8/100)) -> 44.40205 | K14: Tensão máxima em máxima potência | L14: =L$5*(1+(($B$5-25)*L$8/100)) -> 42.71158 | N14: Tensão máxima em máxima potência | O14: =O$5*(1+(($B$5-25)*O$8/100)) -> 41.8 | Q14: Tensão máxima em máxima potência | R14: =R$5*(1+(($B$5-25)*R$8/100)) -> 44.373875 | T14: Tensão máxima em máxima potência | U14: =U$5*(1+(($B$5-25)*U$8/100)) -> 45.423555 | W14: Tensão máxima em máxima potência | X14: =X$5*(1+(($B$5-25)*X$8/100)) -> 48.36825 | Z14: Tensão máxima em máxima potência | AA14: =AA$5*(1+(($B$5-25)*AA$8/100)) -> 43.15874 | AC14: Tensão máxima em máxima potência | AD14: =AD$5*(1+(($B$5-25)*AD$8/100)) -> 42.67915 | AF14: Tensão máxima em máxima potência | AG14: =AG$5*(1+(($B$5-25)*AG$8/100)) -> 45.424895
E15: Corrente máxima de curto-circuito | F15: =F$6*(1+(($B$7-25)*F$9/100)) -> 14.1575 | H15: Corrente máxima de curto-circuito | I15: =I$6*(1+(($B$7-25)*I$9/100)) -> 13.81415 | K15: Corrente máxima de curto-circuito | L15: =L$6*(1+(($B$7-25)*L$9/100)) -> 14.28944 | N15: Corrente máxima de curto-circuito | O15: =O$6*(1+(($B$7-25)*O$9/100)) -> 15.283765 | Q15: Corrente máxima de curto-circuito | R15: =R$6*(1+(($B$7-25)*R$9/100)) -> 14.251575 | T15: Corrente máxima de curto-circuito | U15: =U$6*(1+(($B$7-25)*U$9/100)) -> 14.228288 | W15: Corrente máxima de curto-circuito | X15: =X$6*(1+(($B$7-25)*X$9/100)) -> 14.423402 | Z15: Corrente máxima de curto-circuito | AA15: =AA$6*(1+(($B$7-25)*AA$9/100)) -> 17.9881 | AC15: Corrente máxima de curto-circuito | AD15: =AD$6*(1+(($B$7-25)*AD$9/100)) -> 18.584 | AF15: Corrente máxima de curto-circuito | AG15: =AG$6*(1+(($B$7-25)*AG$9/100)) -> 14.31675
E16: Corrente máxima em máxima potência | F16: =F$7*(1+(($B$7-25)*F$9/100)) -> 13.257487 | H16: Corrente máxima em máxima potência | I16: =I$7*(1+(($B$7-25)*I$9/100)) -> 13.1341 | K16: Corrente máxima em máxima potência | L16: =L$7*(1+(($B$7-25)*L$9/100)) -> 13.70248 | N16: Corrente máxima em máxima potência | O16: =O$7*(1+(($B$7-25)*O$9/100)) -> 14.413875 | Q16: Corrente máxima em máxima potência | R16: =R$7*(1+(($B$7-25)*R$9/100)) -> 13.473298 | T16: Corrente máxima em máxima potência | U16: =U$7*(1+(($B$7-25)*U$9/100)) -> 13.5912 | W16: Corrente máxima em máxima potência | X16: =X$7*(1+(($B$7-25)*X$9/100)) -> 13.766415 | Z16: Corrente máxima em máxima potência | AA16: =AA$7*(1+(($B$7-25)*AA$9/100)) -> 16.9276 | AC16: Corrente máxima em máxima potência | AD16: =AD$7*(1+(($B$7-25)*AD$9/100)) -> 17.5336 | AF16: Corrente máxima em máxima potência | AG16: =AG$7*(1+(($B$7-25)*AG$9/100)) -> 13.26375
A18: INVERSORES | B18: Modelo | C18: ='Compare Inversores'!A$3 -> SIW500G T075 W0 | E18: Quant. Entradas por MPPT | F18: =$C29 -> 2 | H18: Quant. Entradas por MPPT | I18: =$C29 -> 2 | K18: Quant. Entradas por MPPT | L18: =$C29 -> 2 | N18: Quant. Entradas por MPPT | O18: =$C29 -> 2 | Q18: Quant. Entradas por MPPT | R18: =$C29 -> 2 | T18: Quant. Entradas por MPPT | U18: =$C29 -> 2 | W18: Quant. Entradas por MPPT | X18: =$C29 -> 2 | Z18: Quant. Entradas por MPPT | AA18: =$C29 -> 2 | AC18: Quant. Entradas por MPPT | AD18: =$C29 -> 2 | AF18: Quant. Entradas por MPPT | AG18: =$C29 -> 2
B19: Potencia Nominal | C19: =VLOOKUP(C18,inv_Dados,13,0) -> 75000 | E19: Quant. max por MPPT (Isc) | F19: =TRUNC($C27/F$15) -> 2 | H19: Quant. max por MPPT (Isc) | I19: =TRUNC($C27/I$15) -> 2 | K19: Quant. max por MPPT (Isc) | L19: =TRUNC($C27/L$15) -> 2 | N19: Quant. max por MPPT (Isc) | O19: =TRUNC($C27/O$15) -> 2 | Q19: Quant. max por MPPT (Isc) | R19: =TRUNC($C27/R$15) -> 2 | T19: Quant. max por MPPT (Isc) | U19: =TRUNC($C27/U$15) -> 2 | W19: Quant. max por MPPT (Isc) | X19: =TRUNC($C27/X$15) -> 2 | Z19: Quant. max por MPPT (Isc) | AA19: =TRUNC($C27/AA$15) -> 2 | AC19: Quant. max por MPPT (Isc) | AD19: =TRUNC($C27/AD$15) -> 2 | AF19: Quant. max por MPPT (Isc) | AG19: =TRUNC($C27/AG$15) -> 2
B20: Potência com Sobrecarga | C20: =C19*(1+VLOOKUP(C18,inv_Dados,33,0)/100) -> 112500 | E20: Quant. max por MPPT (Ipmax) | F20: =TRUNC($C28*(1+$B$12/100)/F$16) -> 2 | H20: Quant. max por MPPT (Ipmax) | I20: =TRUNC($C28*(1+$B$12/100)/I$16) -> 2 | K20: Quant. max por MPPT (Ipmax) | L20: =TRUNC($C28*(1+$B$12/100)/L$16) -> 2 | N20: Quant. max por MPPT (Ipmax) | O20: =TRUNC($C28*(1+$B$12/100)/O$16) -> 2 | Q20: Quant. max por MPPT (Ipmax) | R20: =TRUNC($C28*(1+$B$12/100)/R$16) -> 2 | T20: Quant. max por MPPT (Ipmax) | U20: =TRUNC($C28*(1+$B$12/100)/U$16) -> 2 | W20: Quant. max por MPPT (Ipmax) | X20: =TRUNC($C28*(1+$B$12/100)/X$16) -> 2 | Z20: Quant. max por MPPT (Ipmax) | AA20: =TRUNC($C28*(1+$B$12/100)/AA$16) -> 1 | AC20: Quant. max por MPPT (Ipmax) | AD20: =TRUNC($C28*(1+$B$12/100)/AD$16) -> 1 | AF20: Quant. max por MPPT (Ipmax) | AG20: =TRUNC($C28*(1+$B$12/100)/AG$16) -> 2
B21: Tensão mínima de entrada | C21: =VLOOKUP(C18,inv_Dados,18,0) -> 200 | E21: Quant. maxima de séries por MPPT | F21: =SMALL(F18:F20,1) -> 2 | H21: Quant. maxima de séries por MPPT | I21: =SMALL(I18:I20,1) -> 2 | K21: Quant. maxima de séries por MPPT | L21: =SMALL(L18:L20,1) -> 2 | N21: Quant. maxima de séries por MPPT | O21: =SMALL(O18:O20,1) -> 2 | Q21: Quant. maxima de séries por MPPT | R21: =SMALL(R18:R20,1) -> 2 | T21: Quant. maxima de séries por MPPT | U21: =SMALL(U18:U20,1) -> 2 | W21: Quant. maxima de séries por MPPT | X21: =SMALL(X18:X20,1) -> 2 | Z21: Quant. maxima de séries por MPPT | AA21: =SMALL(AA18:AA20,1) -> 1 | AC21: Quant. maxima de séries por MPPT | AD21: =SMALL(AD18:AD20,1) -> 1 | AF21: Quant. maxima de séries por MPPT | AG21: =SMALL(AG18:AG20,1) -> 2
B22: Tensão máxima de entrada | C22: =VLOOKUP(C18,inv_Dados,17,0) -> 1100
B23: Tensão mínima de operação | C23: =VLOOKUP(C18,inv_Dados,20,0) -> 200 | E23: Quant. mínima de módulos (Partida) | F23: =ROUNDUP(IF(($C21/F$11)>($C23/F$13),$C21/F$11,$C23/F$13),0) -> 6 | H23: Quant. mínima de módulos (Partida) | I23: =ROUNDUP(IF(($C21/I$11)>($C23/I$13),$C21/I$11,$C23/I$13),0) -> 6 | K23: Quant. mínima de módulos (Partida) | L23: =ROUNDUP(IF(($C21/L$11)>($C23/L$13),$C21/L$11,$C23/L$13),0) -> 6 | N23: Quant. mínima de módulos (Partida) | O23: =ROUNDUP(IF(($C21/O$11)>($C23/O$13),$C21/O$11,$C23/O$13),0) -> 6 | Q23: Quant. mínima de módulos (Partida) | R23: =ROUNDUP(IF(($C21/R$11)>($C23/R$13),$C21/R$11,$C23/R$13),0) -> 5 | T23: Quant. mínima de módulos (Partida) | U23: =ROUNDUP(IF(($C21/U$11)>($C23/U$13),$C21/U$11,$C23/U$13),0) -> 5 | W23: Quant. mínima de módulos (Partida) | X23: =ROUNDUP(IF(($C21/X$11)>($C23/X$13),$C21/X$11,$C23/X$13),0) -> 5 | Z23: Quant. mínima de módulos (Partida) | AA23: =ROUNDUP(IF(($C21/AA$11)>($C23/AA$13),$C21/AA$11,$C23/AA$13),0) -> 6 | AC23: Quant. mínima de módulos (Partida) | AD23: =ROUNDUP(IF(($C21/AD$11)>($C23/AD$13),$C21/AD$11,$C23/AD$13),0) -> 6 | AF23: Quant. mínima de módulos (Partida) | AG23: =ROUNDUP(IF(($C21/AG$11)>($C23/AG$13),$C21/AG$11,$C23/AG$13),0) -> 5
B24: Tensão máxima de operação | C24: =VLOOKUP(C18,inv_Dados,19,0) -> 1000 | E24: Quant. máxima de módulos (Partida) | F24: =TRUNC(IF(($C22/F$12)>($C24/F$14),$C24/F$14,$C22/F$12),0) -> 21 | H24: Quant. máxima de módulos (Partida) | I24: =TRUNC(IF(($C22/I$12)>($C24/I$14),$C24/I$14,$C22/I$12),0) -> 20 | K24: Quant. máxima de módulos (Partida) | L24: =TRUNC(IF(($C22/L$12)>($C24/L$14),$C24/L$14,$C22/L$12),0) -> 21 | N24: Quant. máxima de módulos (Partida) | O24: =TRUNC(IF(($C22/O$12)>($C24/O$14),$C24/O$14,$C22/O$12),0) -> 22 | Q24: Quant. máxima de módulos (Partida) | R24: =TRUNC(IF(($C22/R$12)>($C24/R$14),$C24/R$14,$C22/R$12),0) -> 20 | T24: Quant. máxima de módulos (Partida) | U24: =TRUNC(IF(($C22/U$12)>($C24/U$14),$C24/U$14,$C22/U$12),0) -> 20 | W24: Quant. máxima de módulos (Partida) | X24: =TRUNC(IF(($C22/X$12)>($C24/X$14),$C24/X$14,$C22/X$12),0) -> 18 | Z24: Quant. máxima de módulos (Partida) | AA24: =TRUNC(IF(($C22/AA$12)>($C24/AA$14),$C24/AA$14,$C22/AA$12),0) -> 21 | AC24: Quant. máxima de módulos (Partida) | AD24: =TRUNC(IF(($C22/AD$12)>($C24/AD$14),$C24/AD$14,$C22/AD$12),0) -> 21 | AF24: Quant. máxima de módulos (Partida) | AG24: =TRUNC(IF(($C22/AG$12)>($C24/AG$14),$C24/AG$14,$C22/AG$12),0) -> 20
B25: Tensão mínima em FL (220-230Vac) | C25: =VLOOKUP(C18,inv_Dados,22,0) -> 540 | E25: Quant. mínima em FL | F25: =ROUNDUP(IF(($C25/F$13)>F23,$C25/F$13,F23),0) -> 14 | H25: Quant. mínima em FL | I25: =ROUNDUP(IF(($C25/I$13)>I23,$C25/I$13,I23),0) -> 14 | K25: Quant. mínima em FL | L25: =ROUNDUP(IF(($C25/L$13)>L23,$C25/L$13,L23),0) -> 15 | N25: Quant. mínima em FL | O25: =ROUNDUP(IF(($C25/O$13)>O23,$C25/O$13,O23),0) -> 15 | Q25: Quant. mínima em FL | R25: =ROUNDUP(IF(($C25/R$13)>R23,$C25/R$13,R23),0) -> 14 | T25: Quant. mínima em FL | U25: =ROUNDUP(IF(($C25/U$13)>U23,$C25/U$13,U23),0) -> 14 | W25: Quant. mínima em FL | X25: =ROUNDUP(IF(($C25/X$13)>X23,$C25/X$13,X23),0) -> 13 | Z25: Quant. mínima em FL | AA25: =ROUNDUP(IF(($C25/AA$13)>AA23,$C25/AA$13,AA23),0) -> 14 | AC25: Quant. mínima em FL | AD25: =ROUNDUP(IF(($C25/AD$13)>AD23,$C25/AD$13,AD23),0) -> 15 | AF25: Quant. mínima em FL | AG25: =ROUNDUP(IF(($C25/AG$13)>AG23,$C25/AG$13,AG23),0) -> 14
B26: Tensão máxima em FL (220-230Vac) | C26: =VLOOKUP(C18,inv_Dados,21,0) -> 800 | E26: Quant. máxima em FL | F26: =TRUNC(IF(($C26/F$14)>F24,F24,$C26/F$14),0) -> 18 | H26: Quant. máxima em FL | I26: =TRUNC(IF(($C26/I$14)>I24,I24,$C26/I$14),0) -> 18 | K26: Quant. máxima em FL | L26: =TRUNC(IF(($C26/L$14)>L24,L24,$C26/L$14),0) -> 18 | N26: Quant. máxima em FL | O26: =TRUNC(IF(($C26/O$14)>O24,O24,$C26/O$14),0) -> 19 | Q26: Quant. máxima em FL | R26: =TRUNC(IF(($C26/R$14)>R24,R24,$C26/R$14),0) -> 18 | T26: Quant. máxima em FL | U26: =TRUNC(IF(($C26/U$14)>U24,U24,$C26/U$14),0) -> 17 | W26: Quant. máxima em FL | X26: =TRUNC(IF(($C26/X$14)>X24,X24,$C26/X$14),0) -> 16 | Z26: Quant. máxima em FL | AA26: =TRUNC(IF(($C26/AA$14)>AA24,AA24,$C26/AA$14),0) -> 18 | AC26: Quant. máxima em FL | AD26: =TRUNC(IF(($C26/AD$14)>AD24,AD24,$C26/AD$14),0) -> 18 | AF26: Quant. máxima em FL | AG26: =TRUNC(IF(($C26/AG$14)>AG24,AG24,$C26/AG$14),0) -> 17
B27: Corrente de curto-circuito por MPPT | C27: =VLOOKUP(C18,inv_Dados,24,0) -> 40 | E27: Quant. máxima em Sobrecarga | F27: =IF(($C30*F21*F26*F$3)>($C20*(1+$B$10/100)),INT(($C20*(1+$B$10/100))/F$3),F26*$C30*F21) -> 205 | H27: Quant. máxima em Sobrecarga | I27: =IF(($C30*I21*I26*I$3)>($C20*(1+$B$10/100)),INT(($C20*(1+$B$10/100))/I$3),I26*$C30*I21) -> 205 | K27: Quant. máxima em Sobrecarga | L27: =IF(($C30*L21*L26*L$3)>($C20*(1+$B$10/100)),INT(($C20*(1+$B$10/100))/L$3),L26*$C30*L21) -> 203 | N27: Quant. máxima em Sobrecarga | O27: =IF(($C30*O21*O26*O$3)>($C20*(1+$B$10/100)),INT(($C20*(1+$B$10/100))/O$3),O26*$C30*O21) -> 198 | Q27: Quant. máxima em Sobrecarga | R27: =IF(($C30*R21*R26*R$3)>($C20*(1+$B$10/100)),INT(($C20*(1+$B$10/100))/R$3),R26*$C30*R21) -> 198 | T27: Quant. máxima em Sobrecarga | U27: =IF(($C30*U21*U26*U$3)>($C20*(1+$B$10/100)),INT(($C20*(1+$B$10/100))/U$3),U26*$C30*U21) -> 193 | W27: Quant. máxima em Sobrecarga | X27: =IF(($C30*X21*X26*X$3)>($C20*(1+$B$10/100)),INT(($C20*(1+$B$10/100))/X$3),X26*$C30*X21) -> 178 | Z27: Quant. máxima em Sobrecarga | AA27: =IF(($C30*AA21*AA26*AA$3)>($C20*(1+$B$10/100)),INT(($C20*(1+$B$10/100))/AA$3),AA26*$C30*AA21) -> 161 | AC27: Quant. máxima em Sobrecarga | AD27: =IF(($C30*AD21*AD26*AD$3)>($C20*(1+$B$10/100)),INT(($C20*(1+$B$10/100))/AD$3),AD26*$C30*AD21) -> 159 | AF27: Quant. máxima em Sobrecarga | AG27: =IF(($C30*AG21*AG26*AG$3)>($C20*(1+$B$10/100)),INT(($C20*(1+$B$10/100))/AG$3),AG26*$C30*AG21) -> 196
B28: Corrente max. Operação por MPPT | C28: =VLOOKUP(C18,inv_Dados,25,0) -> 30 | E28: Potencia em kWp | F28: =F27*F$3 -> 112750 | H28: Potencia em kWp | I28: =I27*I$3 -> 112750 | K28: Potencia em kWp | L28: =L27*L$3 -> 112665 | N28: Potencia em kWp | O28: =O27*O$3 -> 112860 | Q28: Potencia em kWp | R28: =R27*R$3 -> 112860 | T28: Potencia em kWp | U28: =U27*U$3 -> 112905 | W28: Potencia em kWp | X28: =X27*X$3 -> 113030 | Z28: Potencia em kWp | AA28: =AA27*AA$3 -> 112700 | AC28: Potencia em kWp | AD28: =AD27*AD$3 -> 112890 | AF28: Potencia em kWp | AG28: =AG27*AG$3 -> 112700
B29: Quant. Entradas por MPPT | C29: =VLOOKUP(C18,inv_Dados,15,0) -> 2
B30: Quant. MPPT | C30: =VLOOKUP(C18,inv_Dados,16,0) -> 10
B32: Modelo | C32: ='Compare Inversores'!A4 -> SIW300H M030 W00 | E32: Quant. Entradas por MPPT | F32: =$C43 -> 1 | H32: Quant. Entradas por MPPT | I32: =$C43 -> 1 | K32: Quant. Entradas por MPPT | L32: =$C43 -> 1 | N32: Quant. Entradas por MPPT | O32: =$C43 -> 1 | Q32: Quant. Entradas por MPPT | R32: =$C43 -> 1 | T32: Quant. Entradas por MPPT | U32: =$C43 -> 1 | W32: Quant. Entradas por MPPT | X32: =$C43 -> 1 | Z32: Quant. Entradas por MPPT | AA32: =$C43 -> 1 | AC32: Quant. Entradas por MPPT | AD32: =$C43 -> 1 | AF32: Quant. Entradas por MPPT | AG32: =$C43 -> 1
B33: Potencia Nominal | C33: =VLOOKUP(C32,inv_Dados,13,0) -> 3000 | E33: Quant. max por MPPT (Isc) | F33: =TRUNC($C41/F$15) -> 1 | H33: Quant. max por MPPT (Isc) | I33: =TRUNC($C41/I$15) -> 1 | K33: Quant. max por MPPT (Isc) | L33: =TRUNC($C41/L$15) -> 1 | N33: Quant. max por MPPT (Isc) | O33: =TRUNC($C41/O$15) -> 1 | Q33: Quant. max por MPPT (Isc) | R33: =TRUNC($C41/R$15) -> 1 | T33: Quant. max por MPPT (Isc) | U33: =TRUNC($C41/U$15) -> 1 | W33: Quant. max por MPPT (Isc) | X33: =TRUNC($C41/X$15) -> 1 | Z33: Quant. max por MPPT (Isc) | AA33: =TRUNC($C41/AA$15) -> 1 | AC33: Quant. max por MPPT (Isc) | AD33: =TRUNC($C41/AD$15) -> 0 | AF33: Quant. max por MPPT (Isc) | AG33: =TRUNC($C41/AG$15) -> 1
B34: Potência com Sobrecarga | C34: =C33*(1+VLOOKUP(C32,inv_Dados,33,0)/100) -> 6000 | E34: Quant. max por MPPT (Ipmax) | F34: =TRUNC($C42*(1+$B$12/100)/F$16) -> 1 | H34: Quant. max por MPPT (Ipmax) | I34: =TRUNC($C42*(1+$B$12/100)/I$16) -> 1 | K34: Quant. max por MPPT (Ipmax) | L34: =TRUNC($C42*(1+$B$12/100)/L$16) -> 1 | N34: Quant. max por MPPT (Ipmax) | O34: =TRUNC($C42*(1+$B$12/100)/O$16) -> 1 | Q34: Quant. max por MPPT (Ipmax) | R34: =TRUNC($C42*(1+$B$12/100)/R$16) -> 1 | T34: Quant. max por MPPT (Ipmax) | U34: =TRUNC($C42*(1+$B$12/100)/U$16) -> 1 | W34: Quant. max por MPPT (Ipmax) | X34: =TRUNC($C42*(1+$B$12/100)/X$16) -> 1 | Z34: Quant. max por MPPT (Ipmax) | AA34: =TRUNC($C42*(1+$B$12/100)/AA$16) -> 0 | AC34: Quant. max por MPPT (Ipmax) | AD34: =TRUNC($C42*(1+$B$12/100)/AD$16) -> 0 | AF34: Quant. max por MPPT (Ipmax) | AG34: =TRUNC($C42*(1+$B$12/100)/AG$16) -> 1
B35: Tensão mínima de entrada | C35: =VLOOKUP(C32,inv_Dados,18,0) -> 100 | E35: Quant. maxima de séries por MPPT | F35: =SMALL(F32:F34,1) -> 1 | H35: Quant. maxima de séries por MPPT | I35: =SMALL(I32:I34,1) -> 1 | K35: Quant. maxima de séries por MPPT | L35: =SMALL(L32:L34,1) -> 1 | N35: Quant. maxima de séries por MPPT | O35: =SMALL(O32:O34,1) -> 1 | Q35: Quant. maxima de séries por MPPT | R35: =SMALL(R32:R34,1) -> 1 | T35: Quant. maxima de séries por MPPT | U35: =SMALL(U32:U34,1) -> 1 | W35: Quant. maxima de séries por MPPT | X35: =SMALL(X32:X34,1) -> 1 | Z35: Quant. maxima de séries por MPPT | AA35: =SMALL(AA32:AA34,1) -> 0 | AC35: Quant. maxima de séries por MPPT | AD35: =SMALL(AD32:AD34,1) -> 0 | AF35: Quant. maxima de séries por MPPT | AG35: =SMALL(AG32:AG34,1) -> 1
B36: Tensão máxima de entrada | C36: =VLOOKUP(C32,inv_Dados,17,0) -> 600
B37: Tensão mínima de operação | C37: =VLOOKUP(C32,inv_Dados,20,0) -> 90 | E37: Quant. mínima de módulos (Partida) | F37: =ROUNDUP(IF(($C35/F$11)>($C37/F$13),$C35/F$11,$C37/F$13),0) -> 3 | H37: Quant. mínima de módulos (Partida) | I37: =ROUNDUP(IF(($C35/I$11)>($C37/I$13),$C35/I$11,$C37/I$13),0) -> 3 | K37: Quant. mínima de módulos (Partida) | L37: =ROUNDUP(IF(($C35/L$11)>($C37/L$13),$C35/L$11,$C37/L$13),0) -> 3 | N37: Quant. mínima de módulos (Partida) | O37: =ROUNDUP(IF(($C35/O$11)>($C37/O$13),$C35/O$11,$C37/O$13),0) -> 3 | Q37: Quant. mínima de módulos (Partida) | R37: =ROUNDUP(IF(($C35/R$11)>($C37/R$13),$C35/R$11,$C37/R$13),0) -> 3 | T37: Quant. mínima de módulos (Partida) | U37: =ROUNDUP(IF(($C35/U$11)>($C37/U$13),$C35/U$11,$C37/U$13),0) -> 3 | W37: Quant. mínima de módulos (Partida) | X37: =ROUNDUP(IF(($C35/X$11)>($C37/X$13),$C35/X$11,$C37/X$13),0) -> 3 | Z37: Quant. mínima de módulos (Partida) | AA37: =ROUNDUP(IF(($C35/AA$11)>($C37/AA$13),$C35/AA$11,$C37/AA$13),0) -> 3 | AC37: Quant. mínima de módulos (Partida) | AD37: =ROUNDUP(IF(($C35/AD$11)>($C37/AD$13),$C35/AD$11,$C37/AD$13),0) -> 3 | AF37: Quant. mínima de módulos (Partida) | AG37: =ROUNDUP(IF(($C35/AG$11)>($C37/AG$13),$C35/AG$11,$C37/AG$13),0) -> 3
B38: Tensão máxima de operação | C38: =VLOOKUP(C32,inv_Dados,19,0) -> 560 | E38: Quant. máxima de módulos (Partida) | F38: =TRUNC(IF(($C36/F$12)>($C38/F$14),$C38/F$14,$C36/F$12),0) -> 11 | H38: Quant. máxima de módulos (Partida) | I38: =TRUNC(IF(($C36/I$12)>($C38/I$14),$C38/I$14,$C36/I$12),0) -> 11 | K38: Quant. máxima de módulos (Partida) | L38: =TRUNC(IF(($C36/L$12)>($C38/L$14),$C38/L$14,$C36/L$12),0) -> 11 | N38: Quant. máxima de módulos (Partida) | O38: =TRUNC(IF(($C36/O$12)>($C38/O$14),$C38/O$14,$C36/O$12),0) -> 12 | Q38: Quant. máxima de módulos (Partida) | R38: =TRUNC(IF(($C36/R$12)>($C38/R$14),$C38/R$14,$C36/R$12),0) -> 11 | T38: Quant. máxima de módulos (Partida) | U38: =TRUNC(IF(($C36/U$12)>($C38/U$14),$C38/U$14,$C36/U$12),0) -> 10 | W38: Quant. máxima de módulos (Partida) | X38: =TRUNC(IF(($C36/X$12)>($C38/X$14),$C38/X$14,$C36/X$12),0) -> 10 | Z38: Quant. máxima de módulos (Partida) | AA38: =TRUNC(IF(($C36/AA$12)>($C38/AA$14),$C38/AA$14,$C36/AA$12),0) -> 11 | AC38: Quant. máxima de módulos (Partida) | AD38: =TRUNC(IF(($C36/AD$12)>($C38/AD$14),$C38/AD$14,$C36/AD$12),0) -> 11 | AF38: Quant. máxima de módulos (Partida) | AG38: =TRUNC(IF(($C36/AG$12)>($C38/AG$14),$C38/AG$14,$C36/AG$12),0) -> 11
B39: Tensão mínima em FL (220-230Vac) | C39: =VLOOKUP(C32,inv_Dados,22,0) -> 90 | E39: Quant. mínima em FL | F39: =ROUNDUP(IF(($C39/F$13)>F37,$C39/F$13,F37),0) -> 3 | H39: Quant. mínima em FL | I39: =ROUNDUP(IF(($C39/I$13)>I37,$C39/I$13,I37),0) -> 3 | K39: Quant. mínima em FL | L39: =ROUNDUP(IF(($C39/L$13)>L37,$C39/L$13,L37),0) -> 3 | N39: Quant. mínima em FL | O39: =ROUNDUP(IF(($C39/O$13)>O37,$C39/O$13,O37),0) -> 3 | Q39: Quant. mínima em FL | R39: =ROUNDUP(IF(($C39/R$13)>R37,$C39/R$13,R37),0) -> 3 | T39: Quant. mínima em FL | U39: =ROUNDUP(IF(($C39/U$13)>U37,$C39/U$13,U37),0) -> 3 | W39: Quant. mínima em FL | X39: =ROUNDUP(IF(($C39/X$13)>X37,$C39/X$13,X37),0) -> 3 | Z39: Quant. mínima em FL | AA39: =ROUNDUP(IF(($C39/AA$13)>AA37,$C39/AA$13,AA37),0) -> 3 | AC39: Quant. mínima em FL | AD39: =ROUNDUP(IF(($C39/AD$13)>AD37,$C39/AD$13,AD37),0) -> 3 | AF39: Quant. mínima em FL | AG39: =ROUNDUP(IF(($C39/AG$13)>AG37,$C39/AG$13,AG37),0) -> 3
B40: Tensão máxima em FL (220-230Vac) | C40: =VLOOKUP(C32,inv_Dados,21,0) -> 560 | E40: Quant. máxima em FL | F40: =TRUNC(IF(($C40/F$14)>F38,F38,$C40/F$14),0) -> 11 | H40: Quant. máxima em FL | I40: =TRUNC(IF(($C40/I$14)>I38,I38,$C40/I$14),0) -> 11 | K40: Quant. máxima em FL | L40: =TRUNC(IF(($C40/L$14)>L38,L38,$C40/L$14),0) -> 11 | N40: Quant. máxima em FL | O40: =TRUNC(IF(($C40/O$14)>O38,O38,$C40/O$14),0) -> 12 | Q40: Quant. máxima em FL | R40: =TRUNC(IF(($C40/R$14)>R38,R38,$C40/R$14),0) -> 11 | T40: Quant. máxima em FL | U40: =TRUNC(IF(($C40/U$14)>U38,U38,$C40/U$14),0) -> 10 | W40: Quant. máxima em FL | X40: =TRUNC(IF(($C40/X$14)>X38,X38,$C40/X$14),0) -> 10 | Z40: Quant. máxima em FL | AA40: =TRUNC(IF(($C40/AA$14)>AA38,AA38,$C40/AA$14),0) -> 11 | AC40: Quant. máxima em FL | AD40: =TRUNC(IF(($C40/AD$14)>AD38,AD38,$C40/AD$14),0) -> 11 | AF40: Quant. máxima em FL | AG40: =TRUNC(IF(($C40/AG$14)>AG38,AG38,$C40/AG$14),0) -> 11
B41: Corrente de curto-circuito por MPPT | C41: =VLOOKUP(C32,inv_Dados,24,0) -> 18 | E41: Quant. máxima em Sobrecarga | F41: =IF(($C44*F35*F40*F$3)>($C34*(1+$B$10/100)),INT(($C34*(1+$B$10/100))/F$3),F40*$C44*F35) -> 10 | H41: Quant. máxima em Sobrecarga | I41: =IF(($C44*I35*I40*I$3)>($C34*(1+$B$10/100)),INT(($C34*(1+$B$10/100))/I$3),I40*$C44*I35) -> 10 | K41: Quant. máxima em Sobrecarga | L41: =IF(($C44*L35*L40*L$3)>($C34*(1+$B$10/100)),INT(($C34*(1+$B$10/100))/L$3),L40*$C44*L35) -> 10 | N41: Quant. máxima em Sobrecarga | O41: =IF(($C44*O35*O40*O$3)>($C34*(1+$B$10/100)),INT(($C34*(1+$B$10/100))/O$3),O40*$C44*O35) -> 10 | Q41: Quant. máxima em Sobrecarga | R41: =IF(($C44*R35*R40*R$3)>($C34*(1+$B$10/100)),INT(($C34*(1+$B$10/100))/R$3),R40*$C44*R35) -> 10 | T41: Quant. máxima em Sobrecarga | U41: =IF(($C44*U35*U40*U$3)>($C34*(1+$B$10/100)),INT(($C34*(1+$B$10/100))/U$3),U40*$C44*U35) -> 10 | W41: Quant. máxima em Sobrecarga | X41: =IF(($C44*X35*X40*X$3)>($C34*(1+$B$10/100)),INT(($C34*(1+$B$10/100))/X$3),X40*$C44*X35) -> 9 | Z41: Quant. máxima em Sobrecarga | AA41: =IF(($C44*AA35*AA40*AA$3)>($C34*(1+$B$10/100)),INT(($C34*(1+$B$10/100))/AA$3),AA40*$C44*AA35) -> 0 | AC41: Quant. máxima em Sobrecarga | AD41: =IF(($C44*AD35*AD40*AD$3)>($C34*(1+$B$10/100)),INT(($C34*(1+$B$10/100))/AD$3),AD40*$C44*AD35) -> 0 | AF41: Quant. máxima em Sobrecarga | AG41: =IF(($C44*AG35*AG40*AG$3)>($C34*(1+$B$10/100)),INT(($C34*(1+$B$10/100))/AG$3),AG40*$C44*AG35) -> 10
B42: Corrente max. Operação por MPPT | C42: =VLOOKUP(C32,inv_Dados,25,0) -> 13.5 | E42: Potencia em kWp | F42: =F41*F$3 -> 5500 | H42: Potencia em kWp | I42: =I41*I$3 -> 5500 | K42: Potencia em kWp | L42: =L41*L$3 -> 5550 | N42: Potencia em kWp | O42: =O41*O$3 -> 5700 | Q42: Potencia em kWp | R42: =R41*R$3 -> 5700 | T42: Potencia em kWp | U42: =U41*U$3 -> 5850 | W42: Potencia em kWp | X42: =X41*X$3 -> 5715 | Z42: Potencia em kWp | AA42: =AA41*AA$3 -> 0 | AC42: Potencia em kWp | AD42: =AD41*AD$3 -> 0 | AF42: Potencia em kWp | AG42: =AG41*AG$3 -> 5750
...

Sheet Inicio
D1: Módulo | G1: Inversor
A2: Módulo | B2: WPV 550 HMM3 | D2: Modelo | E2: =$B$2 -> WPV 550 HMM3 | G2: Modelo | H2: =$B$3 -> SIW200G M030 W1
A3: Inversor | B3: SIW200G M030 W1 | D3: Pôtencia | E3: =VLOOKUP(B2,mod_Dados,9,0) -> 550 | G3: Potencia Nominal | H3: =VLOOKUP($H$2,inv_Dados,13,0) -> 3000
A4: Quantidade de Módulos | B4: 19 | D4: Tensão mínima de circuito aberto | E4: =$E$11*(1+(($B$6-25)*$E$15/100)) -> 46.53175 | G4: Potência de Sobrecarga | H4: =H3*(1+VLOOKUP($H$2,inv_Dados,32,0)/100) -> 3390
A5: Temp. Minima | B5: 10 | D5: Tensão máxima de circuito aberto | E5: =$E$11*(1+(($B$5-25)*$E$15/100)) -> 51.92095 | G5: Tensão mínima de entrada | H5: =VLOOKUP($H$2,inv_Dados,18,0) -> 120
A6: Temp. Maxima | B6: 50 | D6: Tensão mínima em máxima potência | E6: =$E$12*(1+(($B$6-25)*$E$15/100)) -> 39.1277 | G6: Tensão máxima de entrada | H6: =VLOOKUP($H$2,inv_Dados,17,0) -> 600
A7: Tolerância de Potência (%) | B7: 0.5 | D7: Tensão máxima em máxima potência | E7: =$E$12*(1+(($B$5-25)*$E$15/100)) -> 43.65938 | G7: Tensão mínima de operação | H7: =VLOOKUP($H$2,inv_Dados,20,0) -> 80
A8: Tolerância de Corrente de Operação(%) | B8: 10 | D8: Corrente máxima de curto-circuito | E8: =$E$13*(1+(($B$6-25)*$E$16/100)) -> 14.1575 | G8: Tensão máxima de operação | H8: =VLOOKUP($H$2,inv_Dados,19,0) -> 550
D9: Corrente máxima em máxima potência | E9: =$E$14*(1+(($B$6-25)*$E$16/100)) -> 13.257487 | G9: Tensão mínima em FL (220-230Vac) | H9: =VLOOKUP($H$2,inv_Dados,22,0) -> 130
G10: Tensão máxima em FL (220-230Vac) | H10: =VLOOKUP($H$2,inv_Dados,21,0) -> 550
A11: Quant. Max séries por MPPT | B11: =TRUNC(IF(IF(H12*(1+$B$8/100)/E9>H13,H13,H12*(1+$B$8/100)/E9)>(H11/E8),H11/E8,IF(H12*(1+$B$8/100)/E9>H13,H13,H12*(1+$B$8/100)/E9))) -> 1 | D11: Tensão de circuito aberto (STC) | E11: =VLOOKUP($E$2,mod_Dados,10,0) -> 49.9 | G11: Corrente de curto-circuito por MPPT | H11: =VLOOKUP($H$2,inv_Dados,24,0) -> 18
A12: Quant. mínima de módulos | B12: =ROUNDUP(IF((H5/E4)>(H7/E6),H5/E4,H7/E6),0) -> 3 | D12: Tensão em máxima potência (STC) | E12: =VLOOKUP($E$2,mod_Dados,11,0) -> 41.96 | G12: Corrente max. Operação por MPPT | H12: =VLOOKUP($H$2,inv_Dados,25,0) -> 14
A13: Quant. máxima de módulos | B13: =TRUNC(IF((H8/E7)>(H6/E5),H6/E5,H8/E7),0) -> 11 | D13: Corrente de curto-circuito (STC) | E13: =VLOOKUP($E$2,mod_Dados,12,0) -> 14 | G13: Quant. Entradas por MPPT | H13: =VLOOKUP($H$2,inv_Dados,15,0) -> 1
A14: Quant. mínima em FL | B14: =ROUNDUP(IF((H9/E6)>B12,H9/E6,B12),0) -> 4 | D14: Corrente em máxima potência (STC) | E14: =VLOOKUP($E$2,mod_Dados,13,0) -> 13.11 | G14: Quant. MPPT | H14: =VLOOKUP($H$2,inv_Dados,16,0) -> 2
A15: Quant. máxima em FL | B15: =TRUNC(IF((H10/E7)>B13,B13,H10/E7),0) -> 11 | D15: Coef. Temp Voc | E15: =VLOOKUP($E$2,mod_Dados,15,0) -> -0.27
A16: Quant. máxima em Sobrecarga | B16: =IF((H14*B11*B15*E3*(1+$B$7/100))>(H4),INT((H4)/E3),B15*H14*B11) -> 6 | D16: Coef. Temp Isc | E16: =VLOOKUP($E$2,mod_Dados,16,0) -> 0.045
A17: Potência de Sobrecarga | B17: =B16*E3 -> 3300 | D17: Coef. Temp PN | E17: =VLOOKUP($E$2,mod_Dados,14,0) -> -0.35
A19: Quantas strings utilizar em FL
A20: Max | B20: =ROUNDUP(B4/B15,0) -> 2
A21: Min | B21: =ROUND(IF(B11*H14>(B4/B14),B4/B14,B11*H14),0) -> 2

Sheet Dados dos Modulos
A1: Modelo | B1: Fabricante | C1: Face | D1: Estrutura Cristalina | E1: Comprimento (mm) | F1: Largura (mm) | G1: Altura (mm) | H1: Peso (kg) | I1: Potência Nominal (Wp) | J1: Voc (V) | K1: Vpmax (V) | L1: Isc (A) | M1: Ipmax (A) | N1: Coef. Temp. Potência Nominal (%/°C) | O1: Coef. Temp. Tensão de Circuito Aberto (%/°C) | P1: Coef. Temp. Corrente de Curto-Circuito (%/°C) | R1: MANUFACTURER_ID | S1: CELL_TYPE | T1: ACTIVE | V1: MODULO
A2: CHSM72M-HC-405 | B2: ASTRONERGY | C2: MONOFACIAL | D2: MONOCRISTALINO | E2: 2018 | F2: 1002 | G2: 35 | H2: 22.6 | I2: 405 | J2: 49.53 | K2: 41.59 | L2: 10.31 | M2: 9.74 | N2: -0.35 | O2: -0.28 | P2: 0.035 | R2: =IF(B2="WEG","1",IF(B2="HUAWEI","2",IF(B2="FOX ESS","3",IF(B2="GOODWE","4",IF(B2="PHB","5",IF(B2="ASTRONERGY","6",IF(B2="BYD","7",IF(B2="HUASUN","8",IF(B2="JA SOLAR","9",IF(B2="JINKO","10",IF(B2="LONGI","11",IF(B2="RISEN","12",IF(B2="SUNOVA","13",IF(B2="TALESUN","14",IF(B2="TRINA SOLAR","15","NÃO CADASTRADO"))))))))))))))) -> 6 | S2: HALF CELL | T2: 0 | V2: =_xlfn.CONCAT("('",A2,"', ",R2,", ",E2,", ",F2,", ",G2,", ",SUBSTITUTE(H2,",","."),", ",I2,", ",SUBSTITUTE(K2,",","."),", ",SUBSTITUTE(M2,",","."),", ",SUBSTITUTE(J2,",","."),", ",SUBSTITUTE(L2,",","."),", '",D2,"', '",S2,"', '",C2,"', ",SUBSTITUTE(N2,",","."),", ",SUBSTITUTE(O2,",","."),", ",SUBSTITUTE(P2,",","."),", ",T2,"),") -> ('CHSM72M-HC-405', 6, 2018, 1002, 35, 22.6, 405, 41.59, 9.74, 49.53, 10.31, 'MONOCRISTALINO', 'HALF CELL', 'MONOFACIAL', -0.35, -0.28, 0.035, 0),
A3: CHSM72M-HC-410 | B3: ASTRONERGY | C3: MONOFACIAL | D3: MONOCRISTALINO | E3: 2018 | F3: 1002 | G3: 35 | H3: 22.6 | I3: 410 | J3: 49.8 | K3: 41.85 | L3: 10.38 | M3: 9.8 | N3: -0.35 | O3: -0.28 | P3: 0.035 | R3: =IF(B3="WEG","1",IF(B3="HUAWEI","2",IF(B3="FOX ESS","3",IF(B3="GOODWE","4",IF(B3="PHB","5",IF(B3="ASTRONERGY","6",IF(B3="BYD","7",IF(B3="HUASUN","8",IF(B3="JA SOLAR","9",IF(B3="JINKO","10",IF(B3="LONGI","11",IF(B3="RISEN","12",IF(B3="SUNOVA","13",IF(B3="TALESUN","14",IF(B3="TRINA SOLAR","15","NÃO CADASTRADO"))))))))))))))) -> 6 | S3: HALF CELL | T3: 0 | V3: =_xlfn.CONCAT("('",A3,"', ",R3,", ",E3,", ",F3,", ",G3,", ",SUBSTITUTE(H3,",","."),", ",I3,", ",SUBSTITUTE(K3,",","."),", ",SUBSTITUTE(M3,",","."),", ",SUBSTITUTE(J3,",","."),", ",SUBSTITUTE(L3,",","."),", '",D3,"', '",S3,"', '",C3,"', ",SUBSTITUTE(N3,",","."),", ",SUBSTITUTE(O3,",","."),", ",SUBSTITUTE(P3,",","."),", ",T3,"),") -> ('CHSM72M-HC-410', 6, 2018, 1002, 35, 22.6, 410, 41.85, 9.8, 49.8, 10.38, 'MONOCRISTALINO', 'HALF CELL', 'MONOFACIAL', -0.35, -0.28, 0.035, 0),
A4: CHSM72M-HC-415 | B4: ASTRONERGY | C4: MONOFACIAL | D4: MONOCRISTALINO | E4: 2018 | F4: 1002 | G4: 35 | H4: 22.6 | I4: 415 | J4: 50.06 | K4: 42.11 | L4: 10.45 | M4: 9.86 | N4: -0.35 | O4: -0.28 | P4: 0.035 | R4: =IF(B4="WEG","1",IF(B4="HUAWEI","2",IF(B4="FOX ESS","3",IF(B4="GOODWE","4",IF(B4="PHB","5",IF(B4="ASTRONERGY","6",IF(B4="BYD","7",IF(B4="HUASUN","8",IF(B4="JA SOLAR","9",IF(B4="JINKO","10",IF(B4="LONGI","11",IF(B4="RISEN","12",IF(B4="SUNOVA","13",IF(B4="TALESUN","14",IF(B4="TRINA SOLAR","15","NÃO CADASTRADO"))))))))))))))) -> 6 | S4: HALF CELL | T4: 0 | V4: =_xlfn.CONCAT("('",A4,"', ",R4,", ",E4,", ",F4,", ",G4,", ",SUBSTITUTE(H4,",","."),", ",I4,", ",SUBSTITUTE(K4,",","."),", ",SUBSTITUTE(M4,",","."),", ",SUBSTITUTE(J4,",","."),", ",SUBSTITUTE(L4,",","."),", '",D4,"', '",S4,"', '",C4,"', ",SUBSTITUTE(N4,",","."),", ",SUBSTITUTE(O4,",","."),", ",SUBSTITUTE(P4,",","."),", ",T4,"),") -> ('CHSM72M-HC-415', 6, 2018, 1002, 35, 22.6, 415, 42.11, 9.86, 50.06, 10.45, 'MONOCRISTALINO', 'HALF CELL', 'MONOFACIAL', -0.35, -0.28, 0.035, 0),
A5: CHSM72M-HC-420 | B5: ASTRONERGY | C5: MONOFACIAL | D5: MONOCRISTALINO | E5: 2018 | F5: 1002 | G5: 35 | H5: 22.6 | I5: 420 | J5: 50.32 | K5: 42.35 | L5: 10.52 | M5: 9.92 | N5: -0.35 | O5: -0.28 | P5: 0.035 | R5: =IF(B5="WEG","1",IF(B5="HUAWEI","2",IF(B5="FOX ESS","3",IF(B5="GOODWE","4",IF(B5="PHB","5",IF(B5="ASTRONERGY","6",IF(B5="BYD","7",IF(B5="HUASUN","8",IF(B5="JA SOLAR","9",IF(B5="JINKO","10",IF(B5="LONGI","11",IF(B5="RISEN","12",IF(B5="SUNOVA","13",IF(B5="TALESUN","14",IF(B5="TRINA SOLAR","15","NÃO CADASTRADO"))))))))))))))) -> 6 | S5: HALF CELL | T5: 0 | V5: =_xlfn.CONCAT("('",A5,"', ",R5,", ",E5,", ",F5,", ",G5,", ",SUBSTITUTE(H5,",","."),", ",I5,", ",SUBSTITUTE(K5,",","."),", ",SUBSTITUTE(M5,",","."),", ",SUBSTITUTE(J5,",","."),", ",SUBSTITUTE(L5,",","."),", '",D5,"', '",S5,"', '",C5,"', ",SUBSTITUTE(N5,",","."),", ",SUBSTITUTE(O5,",","."),", ",SUBSTITUTE(P5,",","."),", ",T5,"),") -> ('CHSM72M-HC-420', 6, 2018, 1002, 35, 22.6, 420, 42.35, 9.92, 50.32, 10.52, 'MONOCRISTALINO', 'HALF CELL', 'MONOFACIAL', -0.35, -0.28, 0.035, 0),
A6: BYD335PIK-36 | B6: BYD | C6: MONOFACIAL | D6: POLICRISTALINO | E6: 2008 | F6: 1002 | G6: 35 | H6: 21.8 | I6: 335 | J6: 45.44 | K6: 38.1 | L6: 9.25 | M6: 8.79 | N6: -0.35 | O6: -0.285 | P6: 0.057 | R6: =IF(B6="WEG","1",IF(B6="HUAWEI","2",IF(B6="FOX ESS","3",IF(B6="GOODWE","4",IF(B6="PHB","5",IF(B6="ASTRONERGY","6",IF(B6="BYD","7",IF(B6="HUASUN","8",IF(B6="JA SOLAR","9",IF(B6="JINKO","10",IF(B6="LONGI","11",IF(B6="RISEN","12",IF(B6="SUNOVA","13",IF(B6="TALESUN","14",IF(B6="TRINA SOLAR","15","NÃO CADASTRADO"))))))))))))))) -> 7 | S6: HALF CELL | T6: 0 | V6: =_xlfn.CONCAT("('",A6,"', ",R6,", ",E6,", ",F6,", ",G6,", ",SUBSTITUTE(H6,",","."),", ",I6,", ",SUBSTITUTE(K6,",","."),", ",SUBSTITUTE(M6,",","."),", ",SUBSTITUTE(J6,",","."),", ",SUBSTITUTE(L6,",","."),", '",D6,"', '",S6,"', '",C6,"', ",SUBSTITUTE(N6,",","."),", ",SUBSTITUTE(O6,",","."),", ",SUBSTITUTE(P6,",","."),", ",T6,"),") -> ('BYD335PIK-36', 7, 2008, 1002, 35, 21.8, 335, 38.1, 8.79, 45.44, 9.25, 'POLICRISTALINO', 'HALF CELL', 'MONOFACIAL', -0.35, -0.285, 0.057, 0),
A7: BYD340PIK-36 | B7: BYD | C7: MONOFACIAL | D7: POLICRISTALINO | E7: 2008 | F7: 1002 | G7: 35 | H7: 21.8 | I7: 340 | J7: 45.69 | K7: 38.36 | L7: 9.31 | M7: 8.86 | N7: -0.35 | O7: -0.285 | P7: 0.057 | R7: =IF(B7="WEG","1",IF(B7="HUAWEI","2",IF(B7="FOX ESS","3",IF(B7="GOODWE","4",IF(B7="PHB","5",IF(B7="ASTRONERGY","6",IF(B7="BYD","7",IF(B7="HUASUN","8",IF(B7="JA SOLAR","9",IF(B7="JINKO","10",IF(B7="LONGI","11",IF(B7="RISEN","12",IF(B7="SUNOVA","13",IF(B7="TALESUN","14",IF(B7="TRINA SOLAR","15","NÃO CADASTRADO"))))))))))))))) -> 7 | S7: HALF CELL | T7: 0 | V7: =_xlfn.CONCAT("('",A7,"', ",R7,", ",E7,", ",F7,", ",G7,", ",SUBSTITUTE(H7,",","."),", ",I7,", ",SUBSTITUTE(K7,",","."),", ",SUBSTITUTE(M7,",","."),", ",SUBSTITUTE(J7,",","."),", ",SUBSTITUTE(L7,",","."),", '",D7,"', '",S7,"', '",C7,"', ",SUBSTITUTE(N7,",","."),", ",SUBSTITUTE(O7,",","."),", ",SUBSTITUTE(P7,",","."),", ",T7,"),") -> ('BYD340PIK-36', 7, 2008, 1002, 35, 21.8, 340, 38.36, 8.86, 45.69, 9.31, 'POLICRISTALINO', 'HALF CELL', 'MONOFACIAL', -0.35, -0.285, 0.057, 0),
A8: BYD345PIK-36 | B8: BYD | C8: MONOFACIAL | D8: POLICRISTALINO | E8: 2008 | F8: 1002 | G8: 35 | H8: 21.8 | I8: 345 | J8: 45.94 | K8: 38.62 | L8: 9.36 | M8: 8.93 | N8: -0.35 | O8: -0.285 | P8: 0.057 | R8: =IF(B8="WEG","1",IF(B8="HUAWEI","2",IF(B8="FOX ESS","3",IF(B8="GOODWE","4",IF(B8="PHB","5",IF(B8="ASTRONERGY","6",IF(B8="BYD","7",IF(B8="HUASUN","8",IF(B8="JA SOLAR","9",IF(B8="JINKO","10",IF(B8="LONGI","11",IF(B8="RISEN","12",IF(B8="SUNOVA","13",IF(B8="TALESUN","14",IF(B8="TRINA SOLAR","15","NÃO CADASTRADO"))))))))))))))) -> 7 | S8: HALF CELL | T8: 0 | V8: =_xlfn.CONCAT("('",A8,"', ",R8,", ",E8,", ",F8,", ",G8,", ",SUBSTITUTE(H8,",","."),", ",I8,", ",SUBSTITUTE(K8,",","."),", ",SUBSTITUTE(M8,",","."),", ",SUBSTITUTE(J8,",","."),", ",SUBSTITUTE(L8,",","."),", '",D8,"', '",S8,"', '",C8,"', ",SUBSTITUTE(N8,",","."),", ",SUBSTITUTE(O8,",","."),", ",SUBSTITUTE(P8,",","."),", ",T8,"),") -> ('BYD345PIK-36', 7, 2008, 1002, 35, 21.8, 345, 38.62, 8.93, 45.94, 9.36, 'POLICRISTALINO', 'HALF CELL', 'MONOFACIAL', -0.35, -0.285, 0.057, 0),
A9: BYD350PIK-36 | B9: BYD | C9: MONOFACIAL | D9: POLICRISTALINO | E9: 2008 | F9: 1002 | G9: 35 | H9: 21.8 | I9: 350 | J9: 46.19 | K9: 38.87 | L9: 9.42 | M9: 9 | N9: -0.35 | O9: -0.285 | P9: 0.057 | R9: =IF(B9="WEG","1",IF(B9="HUAWEI","2",IF(B9="FOX ESS","3",IF(B9="GOODWE","4",IF(B9="PHB","5",IF(B9="ASTRONERGY","6",IF(B9="BYD","7",IF(B9="HUASUN","8",IF(B9="JA SOLAR","9",IF(B9="JINKO","10",IF(B9="LONGI","11",IF(B9="RISEN","12",IF(B9="SUNOVA","13",IF(B9="TALESUN","14",IF(B9="TRINA SOLAR","15","NÃO CADASTRADO"))))))))))))))) -> 7 | S9: HALF CELL | T9: 0 | V9: =_xlfn.CONCAT("('",A9,"', ",R9,", ",E9,", ",F9,", ",G9,", ",SUBSTITUTE(H9,",","."),", ",I9,", ",SUBSTITUTE(K9,",","."),", ",SUBSTITUTE(M9,",","."),", ",SUBSTITUTE(J9,",","."),", ",SUBSTITUTE(L9,",","."),", '",D9,"', '",S9,"', '",C9,"', ",SUBSTITUTE(N9,",","."),", ",SUBSTITUTE(O9,",","."),", ",SUBSTITUTE(P9,",","."),", ",T9,"),") -> ('BYD350PIK-36', 7, 2008, 1002, 35, 21.8, 350, 38.87, 9, 46.19, 9.42, 'POLICRISTALINO', 'HALF CELL', 'MONOFACIAL', -0.35, -0.285, 0.057, 0),
A10: TSM-390DE09 | B10: TRINA SOLAR | C10: MONOFACIAL | D10: MONOCRISTALINO | E10: 1754 | F10: 1096 | G10: 30 | H10: 21 | I10: 390 | J10: 40.8 | K10: 33.8 | L10: 12.14 | M10: 11.54 | N10: -0.34 | O10: -0.25 | P10: 0.04 | R10: =IF(B10="WEG","1",IF(B10="HUAWEI","2",IF(B10="FOX ESS","3",IF(B10="GOODWE","4",IF(B10="PHB","5",IF(B10="ASTRONERGY","6",IF(B10="BYD","7",IF(B10="HUASUN","8",IF(B10="JA SOLAR","9",IF(B10="JINKO","10",IF(B10="LONGI","11",IF(B10="RISEN","12",IF(B10="SUNOVA","13",IF(B10="TALESUN","14",IF(B10="TRINA SOLAR","15","NÃO CADASTRADO"))))))))))))))) -> 15 | S10: HALF CELL | T10: 0 | V10: =_xlfn.CONCAT("('",A10,"', ",R10,", ",E10,", ",F10,", ",G10,", ",SUBSTITUTE(H10,",","."),", ",I10,", ",SUBSTITUTE(K10,",","."),", ",SUBSTITUTE(M10,",","."),", ",SUBSTITUTE(J10,",","."),", ",SUBSTITUTE(L10,",","."),", '",D10,"', '",S10,"', '",C10,"', ",SUBSTITUTE(N10,",","."),", ",SUBSTITUTE(O10,",","."),", ",SUBSTITUTE(P10,",","."),", ",T10,"),") -> ('TSM-390DE09', 15, 1754, 1096, 30, 21, 390, 33.8, 11.54, 40.8, 12.14, 'MONOCRISTALINO', 'HALF CELL', 'MONOFACIAL', -0.34, -0.25, 0.04, 0),
A11: TSM-395DE09 | B11: TRINA SOLAR | C11: MONOFACIAL | D11: MONOCRISTALINO | E11: 1754 | F11: 1096 | G11: 30 | H11: 21 | I11: 395 | J11: 41 | K11: 34 | L11: 12.21 | M11: 11.62 | N11: -0.34 | O11: -0.25 | P11: 0.04 | R11: =IF(B11="WEG","1",IF(B11="HUAWEI","2",IF(B11="FOX ESS","3",IF(B11="GOODWE","4",IF(B11="PHB","5",IF(B11="ASTRONERGY","6",IF(B11="BYD","7",IF(B11="HUASUN","8",IF(B11="JA SOLAR","9",IF(B11="JINKO","10",IF(B11="LONGI","11",IF(B11="RISEN","12",IF(B11="SUNOVA","13",IF(B11="TALESUN","14",IF(B11="TRINA SOLAR","15","NÃO CADASTRADO"))))))))))))))) -> 15 | S11: HALF CELL | T11: 0 | V11: =_xlfn.CONCAT("('",A11,"', ",R11,", ",E11,", ",F11,", ",G11,", ",SUBSTITUTE(H11,",","."),", ",I11,", ",SUBSTITUTE(K11,",","."),", ",SUBSTITUTE(M11,",","."),", ",SUBSTITUTE(J11,",","."),", ",SUBSTITUTE(L11,",","."),", '",D11,"', '",S11,"', '",C11,"', ",SUBSTITUTE(N11,",","."),", ",SUBSTITUTE(O11,",","."),", ",SUBSTITUTE(P11,",","."),", ",T11,"),") -> ('TSM-395DE09', 15, 1754, 1096, 30, 21, 395, 34, 11.62, 41, 12.21, 'MONOCRISTALINO', 'HALF CELL', 'MONOFACIAL', -0.34, -0.25, 0.04, 0),
